Workbook

Sheet Main Program
A1: 4-Day Condensed Full-Body Training Program (GF / BF)
A2: Shared exercises, individualized set volumes. BF = upper body/arms/back emphasis. GF = back/legs emphasis. Every day is full-body; exercise order is sequenced to minimize consecutive primary/secondary muscle overlap. Max 32 working sets per person per day. Rest 60-90s (isolation), 90-120s (compound). Primary/Secondary Muscles auto-populate from the Exercise DB sheet based on the Exercise name — change the exercise (use the dropdown) and muscles update automatically.
A4: Day | B4: Exercise | C4: Primary Muscles | D4: Secondary Muscles | E4: GF Sets | F4: BF Sets | G4: Reps
A5: Day 1 - Full Body A | B5: Smith Machine Bench Press | C5: =IFERROR(INDEX('Exercise DB'!$B:$B,MATCH($B5,'Exercise DB'!$A:$A,0)),"Not found in db") -> [Chest] | D5: =IFERROR(INDEX('Exercise DB'!$C:$C,MATCH($B5,'Exercise DB'!$A:$A,0)),"Not found in db") -> [Shoulders, Triceps] | E5: 2 | F5: 2 | G5: 8-10
A6: Day 1 - Full Body A | B6: Seated Cable Rows | C6: =IFERROR(INDEX('Exercise DB'!$B:$B,MATCH($B6,'Exercise DB'!$A:$A,0)),"Not found in db") -> [Middle Back] | D6: =IFERROR(INDEX('Exercise DB'!$C:$C,MATCH($B6,'Exercise DB'!$A:$A,0)),"Not found in db") -> [Biceps, Lats, Shoulders] | E6: 4 | F6: 4 | G6: 10-12
A7: Day 1 - Full Body A | B7: Machine Lateral Raise | C7: =IFERROR(INDEX('Exercise DB'!$B:$B,MATCH($B7,'Exercise DB'!$A:$A,0)),"Not found in db") -> [Shoulders] | D7: =IFERROR(INDEX('Exercise DB'!$C:$C,MATCH($B7,'Exercise DB'!$A:$A,0)),"Not found in db") -> [] | E7: 4 | F7: 4 | G7: 12-15
A8: Day 1 - Full Body A | B8: Machine Preacher Curls | C8: =IFERROR(INDEX('Exercise DB'!$B:$B,MATCH($B8,'Exercise DB'!$A:$A,0)),"Not found in db") -> [Biceps] | D8: =IFERROR(INDEX('Exercise DB'!$C:$C,MATCH($B8,'Exercise DB'!$A:$A,0)),"Not found in db") -> [] | E8: 2 | F8: 2 | G8: 10-12
A9: Day 1 - Full Body A | B9: Machine Triceps Extension | C9: =IFERROR(INDEX('Exercise DB'!$B:$B,MATCH($B9,'Exercise DB'!$A:$A,0)),"Not found in db") -> [Triceps] | D9: =IFERROR(INDEX('Exercise DB'!$C:$C,MATCH($B9,'Exercise DB'!$A:$A,0)),"Not found in db") -> [] | E9: 4 | F9: 4 | G9: 10-12
A10: Day 1 - Full Body A | B10: Barbell Hip Thrust | C10: =IFERROR(INDEX('Exercise DB'!$B:$B,MATCH($B10,'Exercise DB'!$A:$A,0)),"Not found in db") -> [Glutes] | D10: =IFERROR(INDEX('Exercise DB'!$C:$C,MATCH($B10,'Exercise DB'!$A:$A,0)),"Not found in db") -> [Calves, Hamstrings] | E10: 3 | F10: 3 | G10: 8-10
A11: Day 1 - Full Body A | B11: Leg Extensions | C11: =IFERROR(INDEX('Exercise DB'!$B:$B,MATCH($B11,'Exercise DB'!$A:$A,0)),"Not found in db") -> [Quadriceps] | D11: =IFERROR(INDEX('Exercise DB'!$C:$C,MATCH($B11,'Exercise DB'!$A:$A,0)),"Not found in db") -> [] | E11: 2 | F11: 2 | G11: 12-15
A12: Day 1 - Full Body A | B12: Thigh Adductor | C12: =IFERROR(INDEX('Exercise DB'!$B:$B,MATCH($B12,'Exercise DB'!$A:$A,0)),"Not found in db") -> [Adductors] | D12: =IFERROR(INDEX('Exercise DB'!$C:$C,MATCH($B12,'Exercise DB'!$A:$A,0)),"Not found in db") -> [Glutes, Hamstrings] | E12: 3 | F12: 3 | G12: 12-15
A13: Day 1 - Full Body A | B13: Ab Crunch Machine | C13: =IFERROR(INDEX('Exercise DB'!$B:$B,MATCH($B13,'Exercise DB'!$A:$A,0)),"Not found in db") -> [Abdominals] | D13: =IFERROR(INDEX('Exercise DB'!$C:$C,MATCH($B13,'Exercise DB'!$A:$A,0)),"Not found in db") -> [] | E13: 2 | F13: 2 | G13: 12-15
A14: Day 1 - Full Body A | B14: Torso Rotation | C14: =IFERROR(INDEX('Exercise DB'!$B:$B,MATCH($B14,'Exercise DB'!$A:$A,0)),"Not found in db") -> [Abdominals] | D14: =IFERROR(INDEX('Exercise DB'!$C:$C,MATCH($B14,'Exercise DB'!$A:$A,0)),"Not found in db") -> [] | E14: 2 | F14: 2 | G14: 12-15
A15: Day 1 - Full Body A | B15: Dumbbell Shrug | C15: =IFERROR(INDEX('Exercise DB'!$B:$B,MATCH($B15,'Exercise DB'!$A:$A,0)),"Not found in db") -> [Traps] | D15: =IFERROR(INDEX('Exercise DB'!$C:$C,MATCH($B15,'Exercise DB'!$A:$A,0)),"Not found in db") -> [] | E15: 3 | F15: 3 | G15: 10-12
B16: Day Total Sets: | E16: =SUM(E5:E15) -> 31 | F16: =SUM(F5:F15) -> 31
A18: Day 2 - Full Body B | B18: Leverage Incline Chest Press | C18: =IFERROR(INDEX('Exercise DB'!$B:$B,MATCH($B18,'Exercise DB'!$A:$A,0)),"Not found in db") -> [Chest] | D18: =IFERROR(INDEX('Exercise DB'!$C:$C,MATCH($B18,'Exercise DB'!$A:$A,0)),"Not found in db") -> [Shoulders, Triceps] | E18: 3 | F18: 3 | G18: 10-12
A19: Day 2 - Full Body B | B19: Pull Through | C19: =IFERROR(INDEX('Exercise DB'!$B:$B,MATCH($B19,'Exercise DB'!$A:$A,0)),"Not found in db") -> [Glutes] | D19: =IFERROR(INDEX('Exercise DB'!$C:$C,MATCH($B19,'Exercise DB'!$A:$A,0)),"Not found in db") -> [Hamstrings, Lower Back] | E19: 3 | F19: 3 | G19: 10-12
A20: Day 2 - Full Body B | B20: Assisted Pull-Up | C20: =IFERROR(INDEX('Exercise DB'!$B:$B,MATCH($B20,'Exercise DB'!$A:$A,0)),"Not found in db") -> [Lats] | D20: =IFERROR(INDEX('Exercise DB'!$C:$C,MATCH($B20,'Exercise DB'!$A:$A,0)),"Not found in db") -> [Biceps, Middle Back] | E20: 4 | F20: 4 | G20: 6-10
A21: Day 2 - Full Body B | B21: Leg Press | C21: =IFERROR(INDEX('Exercise DB'!$B:$B,MATCH($B21,'Exercise DB'!$A:$A,0)),"Not found in db") -> [Quadriceps] | D21: =IFERROR(INDEX('Exercise DB'!$C:$C,MATCH($B21,'Exercise DB'!$A:$A,0)),"Not found in db") -> [Calves, Glutes, Hamstrings] | E21: 3 | F21: 3 | G21: 10-12
A22: Day 2 - Full Body B | B22: Leverage Shoulder Press | C22: =IFERROR(INDEX('Exercise DB'!$B:$B,MATCH($B22,'Exercise DB'!$A:$A,0)),"Not found in db") -> [Shoulders] | D22: =IFERROR(INDEX('Exercise DB'!$C:$C,MATCH($B22,'Exercise DB'!$A:$A,0)),"Not found in db") -> [Triceps] | E22: 3 | F22: 3 | G22: 8-10
A23: Day 2 - Full Body B | B23: Lying Leg Curls | C23: =IFERROR(INDEX('Exercise DB'!$B:$B,MATCH($B23,'Exercise DB'!$A:$A,0)),"Not found in db") -> [Hamstrings] | D23: =IFERROR(INDEX('Exercise DB'!$C:$C,MATCH($B23,'Exercise DB'!$A:$A,0)),"Not found in db") -> [] | E23: 5 | F23: 5 | G23: 10-12
A24: Day 2 - Full Body B | B24: Standing Calf Raises | C24: =IFERROR(INDEX('Exercise DB'!$B:$B,MATCH($B24,'Exercise DB'!$A:$A,0)),"Not found in db") -> [Calves] | D24: =IFERROR(INDEX('Exercise DB'!$C:$C,MATCH($B24,'Exercise DB'!$A:$A,0)),"Not found in db") -> [] | E24: 3 | F24: 3 | G24: 12-15
A25: Day 2 - Full Body B | B25: Reverse Cable Curl | C25: =IFERROR(INDEX('Exercise DB'!$B:$B,MATCH($B25,'Exercise DB'!$A:$A,0)),"Not found in db") -> [Biceps] | D25: =IFERROR(INDEX('Exercise DB'!$C:$C,MATCH($B25,'Exercise DB'!$A:$A,0)),"Not found in db") -> [Forearms] | E25: 2 | F25: 2 | G25: 12-15
A26: Day 2 - Full Body B | B26: Hyperextensions (Back Extensions) | C26: =IFERROR(INDEX('Exercise DB'!$B:$B,MATCH($B26,'Exercise DB'!$A:$A,0)),"Not found in db") -> [Lower Back] | D26: =IFERROR(INDEX('Exercise DB'!$C:$C,MATCH($B26,'Exercise DB'!$A:$A,0)),"Not found in db") -> [Glutes, Hamstrings] | E26: 3 | F26: 3 | G26: 10-12
A27: Day 2 - Full Body B | B27: Dumbbell Shrug | C27: =IFERROR(INDEX('Exercise DB'!$B:$B,MATCH($B27,'Exercise DB'!$A:$A,0)),"Not found in db") -> [Traps] | D27: =IFERROR(INDEX('Exercise DB'!$C:$C,MATCH($B27,'Exercise DB'!$A:$A,0)),"Not found in db") -> [] | E27: 3 | F27: 3 | G27: 10-12
B28: Day Total Sets: | E28: =SUM(E18:E27) -> 32 | F28: =SUM(F18:F27) -> 32
A30: Day 3 - Full Body C | B30: Leverage Chest Press | C30: =IFERROR(INDEX('Exercise DB'!$B:$B,MATCH($B30,'Exercise DB'!$A:$A,0)),"Not found in db") -> [Chest] | D30: =IFERROR(INDEX('Exercise DB'!$C:$C,MATCH($B30,'Exercise DB'!$A:$A,0)),"Not found in db") -> [Shoulders, Triceps] | E30: 2 | F30: 2 | G30: 8-10
A31: Day 3 - Full Body C | B31: Thigh Abductor | C31: =IFERROR(INDEX('Exercise DB'!$B:$B,MATCH($B31,'Exercise DB'!$A:$A,0)),"Not found in db") -> [Abductors] | D31: =IFERROR(INDEX('Exercise DB'!$C:$C,MATCH($B31,'Exercise DB'!$A:$A,0)),"Not found in db") -> [Glutes] | E31: 6 | F31: 6 | G31: 12-15
A32: Day 3 - Full Body C | B32: Assisted Pull-Up | C32: =IFERROR(INDEX('Exercise DB'!$B:$B,MATCH($B32,'Exercise DB'!$A:$A,0)),"Not found in db") -> [Lats] | D32: =IFERROR(INDEX('Exercise DB'!$C:$C,MATCH($B32,'Exercise DB'!$A:$A,0)),"Not found in db") -> [Biceps, Middle Back] | E32: 4 | F32: 4 | G32: 6-10
A33: Day 3 - Full Body C | B33: Leg Extensions | C33: =IFERROR(INDEX('Exercise DB'!$B:$B,MATCH($B33,'Exercise DB'!$A:$A,0)),"Not found in db") -> [Quadriceps] | D33: =IFERROR(INDEX('Exercise DB'!$C:$C,MATCH($B33,'Exercise DB'!$A:$A,0)),"Not found in db") -> [] | E33: 2 | F33: 2 | G33: 12-15
A34: Day 3 - Full Body C | B34: Machine Lateral Raise | C34: =IFERROR(INDEX('Exercise DB'!$B:$B,MATCH($B34,'Exercise DB'!$A:$A,0)),"Not found in db") -> [Shoulders] | D34: =IFERROR(INDEX('Exercise DB'!$C:$C,MATCH($B34,'Exercise DB'!$A:$A,0)),"Not found in db") -> [] | E34: 2 | F34: 2 | G34: 12-15
A35: Day 3 - Full Body C | B35: Seated Leg Curl | C35: =IFERROR(INDEX('Exercise DB'!$B:$B,MATCH($B35,'Exercise DB'!$A:$A,0)),"Not found in db") -> [Hamstrings] | D35: =IFERROR(INDEX('Exercise DB'!$C:$C,MATCH($B35,'Exercise DB'!$A:$A,0)),"Not found in db") -> [] | E35: 4 | F35: 4 | G35: 10-12
A36: Day 3 - Full Body C | B36: Barbell Curl | C36: =IFERROR(INDEX('Exercise DB'!$B:$B,MATCH($B36,'Exercise DB'!$A:$A,0)),"Not found in db") -> [Biceps] | D36: =IFERROR(INDEX('Exercise DB'!$C:$C,MATCH($B36,'Exercise DB'!$A:$A,0)),"Not found in db") -> [Forearms] | E36: 3 | F36: 3 | G36: 8-10
A37: Day 3 - Full Body C | B37: Thigh Adductor | C37: =IFERROR(INDEX('Exercise DB'!$B:$B,MATCH($B37,'Exercise DB'!$A:$A,0)),"Not found in db") -> [Adductors] | D37: =IFERROR(INDEX('Exercise DB'!$C:$C,MATCH($B37,'Exercise DB'!$A:$A,0)),"Not found in db") -> [Glutes, Hamstrings] | E37: 3 | F37: 3 | G37: 12-15
A38: Day 3 - Full Body C | B38: Cable Rope Overhead Triceps Extension | C38: =IFERROR(INDEX('Exercise DB'!$B:$B,MATCH($B38,'Exercise DB'!$A:$A,0)),"Not found in db") -> [Triceps] | D38: =IFERROR(INDEX('Exercise DB'!$C:$C,MATCH($B38,'Exercise DB'!$A:$A,0)),"Not found in db") -> [] | E38: 3 | F38: 3 | G38: 10-12
A39: Day 3 - Full Body C | B39: Ab Crunch Machine | C39: =IFERROR(INDEX('Exercise DB'!$B:$B,MATCH($B39,'Exercise DB'!$A:$A,0)),"Not found in db") -> [Abdominals] | D39: =IFERROR(INDEX('Exercise DB'!$C:$C,MATCH($B39,'Exercise DB'!$A:$A,0)),"Not found in db") -> [] | E39: 3 | F39: 3 | G39: 12-15
B40: Day Total Sets: | E40: =SUM(E30:E39) -> 32 | F40: =SUM(F30:F39) -> 32
A42: Day 4 - Full Body D | B42: Butterfly | C42: =IFERROR(INDEX('Exercise DB'!$B:$B,MATCH($B42,'Exercise DB'!$A:$A,0)),"Not found in db") -> [Chest] | D42: =IFERROR(INDEX('Exercise DB'!$C:$C,MATCH($B42,'Exercise DB'!$A:$A,0)),"Not found in db") -> [] | E42: 3 | F42: 3 | G42: 12-15
A43: Day 4 - Full Body D | B43: Glute Kickback | C43: =IFERROR(INDEX('Exercise DB'!$B:$B,MATCH($B43,'Exercise DB'!$A:$A,0)),"Not found in db") -> [Glutes] | D43: =IFERROR(INDEX('Exercise DB'!$C:$C,MATCH($B43,'Exercise DB'!$A:$A,0)),"Not found in db") -> [Hamstrings] | E43: 3 | F43: 3 | G43: 12-15
A44: Day 4 - Full Body D | B44: Seated Cable Rows | C44: =IFERROR(INDEX('Exercise DB'!$B:$B,MATCH($B44,'Exercise DB'!$A:$A,0)),"Not found in db") -> [Middle Back] | D44: =IFERROR(INDEX('Exercise DB'!$C:$C,MATCH($B44,'Exercise DB'!$A:$A,0)),"Not found in db") -> [Biceps, Lats, Shoulders] | E44: 3 | F44: 3 | G44: 10-12
...

Sheet Muscle Points (Primary Only)
A1: Weekly Muscle Points - Primary Muscle Only (1 point per set)
A2: Target: ~10-20 points/muscle/week, except muscles with an explicit set target below.
A4: Muscle | B4: GF Points | C4: BF Points | D4: Target | E4: GF Status | F4: BF Status
A5: Chest | B5: =SUMPRODUCT(ISNUMBER(SEARCH($A5,'Main Program'!$C$5:$C$52))*'Main Program'!$E$5:$E$52) -> 10 | C5: =SUMPRODUCT(ISNUMBER(SEARCH($A5,'Main Program'!$C$5:$C$52))*'Main Program'!$F$5:$F$52) -> 10 | D5: 10-20 | E5: =IF(AND(B5>=10,B5<=20),"Within 10-20",IF(B5<10,"Below range","Above range")) -> Within 10-20 | F5: =IF(AND(C5>=10,C5<=20),"Within 10-20",IF(C5<10,"Below range","Above range")) -> Within 10-20
A6: Middle Back | B6: =SUMPRODUCT(ISNUMBER(SEARCH($A6,'Main Program'!$C$5:$C$52))*'Main Program'!$E$5:$E$52) -> 7 | C6: =SUMPRODUCT(ISNUMBER(SEARCH($A6,'Main Program'!$C$5:$C$52))*'Main Program'!$F$5:$F$52) -> 7 | D6: 10-20 | E6: =IF(AND(B6>=10,B6<=20),"Within 10-20",IF(B6<10,"Below range","Above range")) -> Below range | F6: =IF(AND(C6>=10,C6<=20),"Within 10-20",IF(C6<10,"Below range","Above range")) -> Below range
A7: Lats | B7: =SUMPRODUCT(ISNUMBER(SEARCH($A7,'Main Program'!$C$5:$C$52))*'Main Program'!$E$5:$E$52) -> 8 | C7: =SUMPRODUCT(ISNUMBER(SEARCH($A7,'Main Program'!$C$5:$C$52))*'Main Program'!$F$5:$F$52) -> 8 | D7: 10-20 | E7: =IF(AND(B7>=10,B7<=20),"Within 10-20",IF(B7<10,"Below range","Above range")) -> Below range | F7: =IF(AND(C7>=10,C7<=20),"Within 10-20",IF(C7<10,"Below range","Above range")) -> Below range
A8: Traps | B8: =SUMPRODUCT(ISNUMBER(SEARCH($A8,'Main Program'!$C$5:$C$52))*'Main Program'!$E$5:$E$52) -> 9 | C8: =SUMPRODUCT(ISNUMBER(SEARCH($A8,'Main Program'!$C$5:$C$52))*'Main Program'!$F$5:$F$52) -> 9 | D8: 10-20 | E8: =IF(AND(B8>=10,B8<=20),"Within 10-20",IF(B8<10,"Below range","Above range")) -> Below range | F8: =IF(AND(C8>=10,C8<=20),"Within 10-20",IF(C8<10,"Below range","Above range")) -> Below range
A9: Shoulders | B9: =SUMPRODUCT(ISNUMBER(SEARCH($A9,'Main Program'!$C$5:$C$52))*'Main Program'!$E$5:$E$52) -> 12 | C9: =SUMPRODUCT(ISNUMBER(SEARCH($A9,'Main Program'!$C$5:$C$52))*'Main Program'!$F$5:$F$52) -> 12 | D9: 10-20 | E9: =IF(AND(B9>=10,B9<=20),"Within 10-20",IF(B9<10,"Below range","Above range")) -> Within 10-20 | F9: =IF(AND(C9>=10,C9<=20),"Within 10-20",IF(C9<10,"Below range","Above range")) -> Within 10-20
A10: Biceps | B10: =SUMPRODUCT(ISNUMBER(SEARCH($A10,'Main Program'!$C$5:$C$52))*'Main Program'!$E$5:$E$52) -> 11 | C10: =SUMPRODUCT(ISNUMBER(SEARCH($A10,'Main Program'!$C$5:$C$52))*'Main Program'!$F$5:$F$52) -> 11 | D10: 10-20 | E10: =IF(AND(B10>=10,B10<=20),"Within 10-20",IF(B10<10,"Below range","Above range")) -> Within 10-20 | F10: =IF(AND(C10>=10,C10<=20),"Within 10-20",IF(C10<10,"Below range","Above range")) -> Within 10-20
A11: Triceps | B11: =SUMPRODUCT(ISNUMBER(SEARCH($A11,'Main Program'!$C$5:$C$52))*'Main Program'!$E$5:$E$52) -> 7 | C11: =SUMPRODUCT(ISNUMBER(SEARCH($A11,'Main Program'!$C$5:$C$52))*'Main Program'!$F$5:$F$52) -> 7 | D11: 10-20 | E11: =IF(AND(B11>=10,B11<=20),"Within 10-20",IF(B11<10,"Below range","Above range")) -> Below range | F11: =IF(AND(C11>=10,C11<=20),"Within 10-20",IF(C11<10,"Below range","Above range")) -> Below range
A12: Forearms | B12: =SUMPRODUCT(ISNUMBER(SEARCH($A12,'Main Program'!$C$5:$C$52))*'Main Program'!$E$5:$E$52) -> 0 | C12: =SUMPRODUCT(ISNUMBER(SEARCH($A12,'Main Program'!$C$5:$C$52))*'Main Program'!$F$5:$F$52) -> 0 | D12: 10-20 | E12: =IF(AND(B12>=10,B12<=20),"Within 10-20",IF(B12<10,"Below range","Above range")) -> Below range | F12: =IF(AND(C12>=10,C12<=20),"Within 10-20",IF(C12<10,"Below range","Above range")) -> Below range
A13: Abdominals | B13: =SUMPRODUCT(ISNUMBER(SEARCH($A13,'Main Program'!$C$5:$C$52))*'Main Program'!$E$5:$E$52) -> 10 | C13: =SUMPRODUCT(ISNUMBER(SEARCH($A13,'Main Program'!$C$5:$C$52))*'Main Program'!$F$5:$F$52) -> 10 | D13: 10-20 | E13: =IF(AND(B13>=10,B13<=20),"Within 10-20",IF(B13<10,"Below range","Above range")) -> Within 10-20 | F13: =IF(AND(C13>=10,C13<=20),"Within 10-20",IF(C13<10,"Below range","Above range")) -> Within 10-20
A14: Glutes | B14: =SUMPRODUCT(ISNUMBER(SEARCH($A14,'Main Program'!$C$5:$C$52))*'Main Program'!$E$5:$E$52) -> 9 | C14: =SUMPRODUCT(ISNUMBER(SEARCH($A14,'Main Program'!$C$5:$C$52))*'Main Program'!$F$5:$F$52) -> 9 | D14: 10-20 | E14: =IF(AND(B14>=10,B14<=20),"Within 10-20",IF(B14<10,"Below range","Above range")) -> Below range | F14: =IF(AND(C14>=10,C14<=20),"Within 10-20",IF(C14<10,"Below range","Above range")) -> Below range
A15: Quadriceps | B15: =SUMPRODUCT(ISNUMBER(SEARCH($A15,'Main Program'!$C$5:$C$52))*'Main Program'!$E$5:$E$52) -> 10 | C15: =SUMPRODUCT(ISNUMBER(SEARCH($A15,'Main Program'!$C$5:$C$52))*'Main Program'!$F$5:$F$52) -> 10 | D15: 10-20 | E15: =IF(AND(B15>=10,B15<=20),"Within 10-20",IF(B15<10,"Below range","Above range")) -> Within 10-20 | F15: =IF(AND(C15>=10,C15<=20),"Within 10-20",IF(C15<10,"Below range","Above range")) -> Within 10-20
A16: Hamstrings | B16: =SUMPRODUCT(ISNUMBER(SEARCH($A16,'Main Program'!$C$5:$C$52))*'Main Program'!$E$5:$E$52) -> 9 | C16: =SUMPRODUCT(ISNUMBER(SEARCH($A16,'Main Program'!$C$5:$C$52))*'Main Program'!$F$5:$F$52) -> 9 | D16: 10-20 | E16: =IF(AND(B16>=10,B16<=20),"Within 10-20",IF(B16<10,"Below range","Above range")) -> Below range | F16: =IF(AND(C16>=10,C16<=20),"Within 10-20",IF(C16<10,"Below range","Above range")) -> Below range
... A21: Neck | B21: =SUMPRODUCT(ISNUMBER(SEARCH($A21,'Main Program'!$C$5:$C$52))*'Main Program'!$E$5:$E$52) -> 0 | C21: =SUMPRODUCT(ISNUMBER(SEARCH($A21,'Main Program'!$C$5:$C$52))*'Main Program'!$F$5:$F$52) -> 0 | D21: 10-20 | E21: =IF(AND(B21>=10,B21<=20),"Within 10-20",IF(B21<10,"Below range","Above range")) -> Below range | F21: =IF(AND(C21>=10,C21<=20),"Within 10-20",IF(C21<10,"Below range","Above range")) -> Below range
A23: Note: Status is based solely on the 10-20 sets/week range for every muscle. Points count any exercise whose Primary Muscles list contains that muscle (substring match), so this table stays accurate even as you swap exercises via the dropdown.

Sheet Muscle Pts (Primary+Secondary)
A1: Weekly Muscle Points - Primary (1 pt) + Secondary (0.5 pt) per Set
A2: Target: ~10-20 points/muscle/week, except muscles with an explicit set target below (target column reflects the primary-only set target).
A4: Muscle | B4: GF Points | C4: BF Points | D4: Target | E4: GF Status | F4: BF Status
A5: Chest | B5: =SUMPRODUCT(ISNUMBER(SEARCH($A5,'Main Program'!$C$5:$C$52))*'Main Program'!$E$5:$E$52)+0.5*SUMPRODUCT(ISNUMBER(SEARCH($A5,'Main Program'!$D$5:$D$52))*'Main Program'!$E$5:$E$52) -> 10 | C5: =SUMPRODUCT(ISNUMBER(SEARCH($A5,'Main Program'!$C$5:$C$52))*'Main Program'!$F$5:$F$52)+0.5*SUMPRODUCT(ISNUMBER(SEARCH($A5,'Main Program'!$D$5:$D$52))*'Main Program'!$F$5:$F$52) -> 10 | D5: 10-20 | E5: =IF(AND(B5>=10,B5<=20),"Within 10-20",IF(B5<10,"Below range","Above range")) -> Within 10-20 | F5: =IF(AND(C5>=10,C5<=20),"Within 10-20",IF(C5<10,"Below range","Above range")) -> Within 10-20
A6: Middle Back | B6: =SUMPRODUCT(ISNUMBER(SEARCH($A6,'Main Program'!$C$5:$C$52))*'Main Program'!$E$5:$E$52)+0.5*SUMPRODUCT(ISNUMBER(SEARCH($A6,'Main Program'!$D$5:$D$52))*'Main Program'!$E$5:$E$52) -> 11 | C6: =SUMPRODUCT(ISNUMBER(SEARCH($A6,'Main Program'!$C$5:$C$52))*'Main Program'!$F$5:$F$52)+0.5*SUMPRODUCT(ISNUMBER(SEARCH($A6,'Main Program'!$D$5:$D$52))*'Main Program'!$F$5:$F$52) -> 11 | D6: 10-20 | E6: =IF(AND(B6>=10,B6<=20),"Within 10-20",IF(B6<10,"Below range","Above range")) -> Within 10-20 | F6: =IF(AND(C6>=10,C6<=20),"Within 10-20",IF(C6<10,"Below range","Above range")) -> Within 10-20
A7: Lats | B7: =SUMPRODUCT(ISNUMBER(SEARCH($A7,'Main Program'!$C$5:$C$52))*'Main Program'!$E$5:$E$52)+0.5*SUMPRODUCT(ISNUMBER(SEARCH($A7,'Main Program'!$D$5:$D$52))*'Main Program'!$E$5:$E$52) -> 11.5 | C7: =SUMPRODUCT(ISNUMBER(SEARCH($A7,'Main Program'!$C$5:$C$52))*'Main Program'!$F$5:$F$52)+0.5*SUMPRODUCT(ISNUMBER(SEARCH($A7,'Main Program'!$D$5:$D$52))*'Main Program'!$F$5:$F$52) -> 11.5 | D7: 10-20 | E7: =IF(AND(B7>=10,B7<=20),"Within 10-20",IF(B7<10,"Below range","Above range")) -> Within 10-20 | F7: =IF(AND(C7>=10,C7<=20),"Within 10-20",IF(C7<10,"Below range","Above range")) -> Within 10-20
A8: Traps | B8: =SUMPRODUCT(ISNUMBER(SEARCH($A8,'Main Program'!$C$5:$C$52))*'Main Program'!$E$5:$E$52)+0.5*SUMPRODUCT(ISNUMBER(SEARCH($A8,'Main Program'!$D$5:$D$52))*'Main Program'!$E$5:$E$52) -> 9 | C8: =SUMPRODUCT(ISNUMBER(SEARCH($A8,'Main Program'!$C$5:$C$52))*'Main Program'!$F$5:$F$52)+0.5*SUMPRODUCT(ISNUMBER(SEARCH($A8,'Main Program'!$D$5:$D$52))*'Main Program'!$F$5:$F$52) -> 9 | D8: 10-20 | E8: =IF(AND(B8>=10,B8<=20),"Within 10-20",IF(B8<10,"Below range","Above range")) -> Below range | F8: =IF(AND(C8>=10,C8<=20),"Within 10-20",IF(C8<10,"Below range","Above range")) -> Below range
A9: Shoulders | B9: =SUMPRODUCT(ISNUMBER(SEARCH($A9,'Main Program'!$C$5:$C$52))*'Main Program'!$E$5:$E$52)+0.5*SUMPRODUCT(ISNUMBER(SEARCH($A9,'Main Program'!$D$5:$D$52))*'Main Program'!$E$5:$E$52) -> 19 | C9: =SUMPRODUCT(ISNUMBER(SEARCH($A9,'Main Program'!$C$5:$C$52))*'Main Program'!$F$5:$F$52)+0.5*SUMPRODUCT(ISNUMBER(SEARCH($A9,'Main Program'!$D$5:$D$52))*'Main Program'!$F$5:$F$52) -> 19 | D9: 10-20 | E9: =IF(AND(B9>=10,B9<=20),"Within 10-20",IF(B9<10,"Below range","Above range")) -> Within 10-20 | F9: =IF(AND(C9>=10,C9<=20),"Within 10-20",IF(C9<10,"Below range","Above range")) -> Within 10-20
A10: Biceps | B10: =SUMPRODUCT(ISNUMBER(SEARCH($A10,'Main Program'!$C$5:$C$52))*'Main Program'!$E$5:$E$52)+0.5*SUMPRODUCT(ISNUMBER(SEARCH($A10,'Main Program'!$D$5:$D$52))*'Main Program'!$E$5:$E$52) -> 18.5 | C10: =SUMPRODUCT(ISNUMBER(SEARCH($A10,'Main Program'!$C$5:$C$52))*'Main Program'!$F$5:$F$52)+0.5*SUMPRODUCT(ISNUMBER(SEARCH($A10,'Main Program'!$D$5:$D$52))*'Main Program'!$F$5:$F$52) -> 18.5 | D10: 10-20 | E10: =IF(AND(B10>=10,B10<=20),"Within 10-20",IF(B10<10,"Below range","Above range")) -> Within 10-20 | F10: =IF(AND(C10>=10,C10<=20),"Within 10-20",IF(C10<10,"Below range","Above range")) -> Within 10-20
A11: Triceps | B11: =SUMPRODUCT(ISNUMBER(SEARCH($A11,'Main Program'!$C$5:$C$52))*'Main Program'!$E$5:$E$52)+0.5*SUMPRODUCT(ISNUMBER(SEARCH($A11,'Main Program'!$D$5:$D$52))*'Main Program'!$E$5:$E$52) -> 13.5 | C11: =SUMPRODUCT(ISNUMBER(SEARCH($A11,'Main Program'!$C$5:$C$52))*'Main Program'!$F$5:$F$52)+0.5*SUMPRODUCT(ISNUMBER(SEARCH($A11,'Main Program'!$D$5:$D$52))*'Main Program'!$F$5:$F$52) -> 13.5 | D11: 10-20 | E11: =IF(AND(B11>=10,B11<=20),"Within 10-20",IF(B11<10,"Below range","Above range")) -> Within 10-20 | F11: =IF(AND(C11>=10,C11<=20),"Within 10-20",IF(C11<10,"Below range","Above range")) -> Within 10-20
A12: Forearms | B12: =SUMPRODUCT(ISNUMBER(SEARCH($A12,'Main Program'!$C$5:$C$52))*'Main Program'!$E$5:$E$52)+0.5*SUMPRODUCT(ISNUMBER(SEARCH($A12,'Main Program'!$D$5:$D$52))*'Main Program'!$E$5:$E$52) -> 3.5 | C12: =SUMPRODUCT(ISNUMBER(SEARCH($A12,'Main Program'!$C$5:$C$52))*'Main Program'!$F$5:$F$52)+0.5*SUMPRODUCT(ISNUMBER(SEARCH($A12,'Main Program'!$D$5:$D$52))*'Main Program'!$F$5:$F$52) -> 3.5 | D12: 10-20 | E12: =IF(AND(B12>=10,B12<=20),"Within 10-20",IF(B12<10,"Below range","Above range")) -> Below range | F12: =IF(AND(C12>=10,C12<=20),"Within 10-20",IF(C12<10,"Below range","Above range")) -> Below range
A13: Abdominals | B13: =SUMPRODUCT(ISNUMBER(SEARCH($A13,'Main Program'!$C$5:$C$52))*'Main Program'!$E$5:$E$52)+0.5*SUMPRODUCT(ISNUMBER(SEARCH($A13,'Main Program'!$D$5:$D$52))*'Main Program'!$E$5:$E$52) -> 10 | C13: =SUMPRODUCT(ISNUMBER(SEARCH($A13,'Main Program'!$C$5:$C$52))*'Main Program'!$F$5:$F$52)+0.5*SUMPRODUCT(ISNUMBER(SEARCH($A13,'Main Program'!$D$5:$D$52))*'Main Program'!$F$5:$F$52) -> 10 | D13: 10-20 | E13: =IF(AND(B13>=10,B13<=20),"Within 10-20",IF(B13<10,"Below range","Above range")) -> Within 10-20 | F13: =IF(AND(C13>=10,C13<=20),"Within 10-20",IF(C13<10,"Below range","Above range")) -> Within 10-20
A14: Glutes | B14: =SUMPRODUCT(ISNUMBER(SEARCH($A14,'Main Program'!$C$5:$C$52))*'Main Program'!$E$5:$E$52)+0.5*SUMPRODUCT(ISNUMBER(SEARCH($A14,'Main Program'!$D$5:$D$52))*'Main Program'!$E$5:$E$52) -> 21 | C14: =SUMPRODUCT(ISNUMBER(SEARCH($A14,'Main Program'!$C$5:$C$52))*'Main Program'!$F$5:$F$52)+0.5*SUMPRODUCT(ISNUMBER(SEARCH($A14,'Main Program'!$D$5:$D$52))*'Main Program'!$F$5:$F$52) -> 21 | D14: 10-20 | E14: =IF(AND(B14>=10,B14<=20),"Within 10-20",IF(B14<10,"Below range","Above range")) -> Above range | F14: =IF(AND(C14>=10,C14<=20),"Within 10-20",IF(C14<10,"Below range","Above range")) -> Above range
A15: Quadriceps | B15: =SUMPRODUCT(ISNUMBER(SEARCH($A15,'Main Program'!$C$5:$C$52))*'Main Program'!$E$5:$E$52)+0.5*SUMPRODUCT(ISNUMBER(SEARCH($A15,'Main Program'!$D$5:$D$52))*'Main Program'!$E$5:$E$52) -> 10 | C15: =SUMPRODUCT(ISNUMBER(SEARCH($A15,'Main Program'!$C$5:$C$52))*'Main Program'!$F$5:$F$52)+0.5*SUMPRODUCT(ISNUMBER(SEARCH($A15,'Main Program'!$D$5:$D$52))*'Main Program'!$F$5:$F$52) -> 10 | D15: 10-20 | E15: =IF(AND(B15>=10,B15<=20),"Within 10-20",IF(B15<10,"Below range","Above range")) -> Within 10-20 | F15: =IF(AND(C15>=10,C15<=20),"Within 10-20",IF(C15<10,"Below range","Above range")) -> Within 10-20
A16: Hamstrings | B16: =SUMPRODUCT(ISNUMBER(SEARCH($A16,'Main Program'!$C$5:$C$52))*'Main Program'!$E$5:$E$52)+0.5*SUMPRODUCT(ISNUMBER(SEARCH($A16,'Main Program'!$D$5:$D$52))*'Main Program'!$E$5:$E$52) -> 22.5 | C16: =SUMPRODUCT(ISNUMBER(SEARCH($A16,'Main Program'!$C$5:$C$52))*'Main Program'!$F$5:$F$52)+0.5*SUMPRODUCT(ISNUMBER(SEARCH($A16,'Main Program'!$D$5:$D$52))*'Main Program'!$F$5:$F$52) -> 22.5 | D16: 10-20 | E16: =IF(AND(B16>=10,B16<=20),"Within 10-20",IF(B16<10,"Below range","Above range")) -> Above range | F16: =IF(AND(C16>=10,C16<=20),"Within 10-20",IF(C16<10,"Below range","Above range")) -> Above range
... A21: Neck | B21: =SUMPRODUCT(ISNUMBER(SEARCH($A21,'Main Program'!$C$5:$C$52))*'Main Program'!$E$5:$E$52)+0.5*SUMPRODUCT(ISNUMBER(SEARCH($A21,'Main Program'!$D$5:$D$52))*'Main Program'!$E$5:$E$52) -> 0 | C21: =SUMPRODUCT(ISNUMBER(SEARCH($A21,'Main Program'!$C$5:$C$52))*'Main Program'!$F$5:$F$52)+0.5*SUMPRODUCT(ISNUMBER(SEARCH($A21,'Main Program'!$D$5:$D$52))*'Main Program'!$F$5:$F$52) -> 0 | D21: 10-20 | E21: =IF(AND(B21>=10,B21<=20),"Within 10-20",IF(B21<10,"Below range","Above range")) -> Below range | F21: =IF(AND(C21>=10,C21<=20),"Within 10-20",IF(C21<10,"Below range","Above range")) -> Below range
A23: Note: Status is based solely on the 10-20 sets/week range for every muscle. Secondary-muscle contributions are 0.5 pt/set and counted whenever that muscle appears anywhere in the Secondary Muscles list for a set.

Sheet Exercise DB
A1: Exercise Name | B1: Primary Muscles | C1: Secondary Muscles
A2: 3/4 Sit-Up | B2: [Abdominals] | C2: []
A3: 90/90 Hamstring | B3: [Hamstrings] | C3: [Calves]
A4: Ab Crunch Machine | B4: [Abdominals] | C4: []
A5: Ab Roller | B5: [Abdominals] | C5: [Shoulders]
A6: Adductor | B6: [Adductors] | C6: []
A7: Adductor/Groin | B7: [Adductors] | C7: []
A8: Advanced Kettlebell Windmill | B8: [Abdominals] | C8: [Glutes, Hamstrings, Shoulders]
A9: Air Bike | B9: [Abdominals] | C9: []
A10: All Fours Quad Stretch | B10: [Quadriceps] | C10: [Quadriceps]
A11: Alternate Hammer Curl | B11: [Biceps] | C11: [Forearms]
A12: Alternate Heel Touchers | B12: [Abdominals] | C12: []
... A879: Machine Lateral Raise | B879: [Shoulders] | C879: []
